<?xml version="1.0"?>

<robot xmlns:xacro="http://ros.org/wiki/xacro">
  <material name="black">
    <color rgba="0.2 0.2 0.2 1.0"/>
  </material>
  <material name="grey">
    <color rgba="0.3 0.3 0.3 1.0"/>
  </material>

  <link name="base_link"/>

  <link name="${NAME_LINK_BASE}">
    <visual>
      <origin xyz="0 0 0" rpy="0 0 0"/>
      <geometry>
        <mesh filename="package://${MESH_LINK_BASE}"
            scale="1 1 1"/>
      </geometry>
      <material name="black"/>
    </visual>

    <collision>
      <origin xyz="0 0 0" rpy="0 0 0"/>
      <geometry>
        <mesh filename="package://${MESH_COLLISION_LINK_BASE}"
            scale="1 1 1"/>
      </geometry>
      <material name="black"/>
    </collision>

    <inertial>
      <mass value="0.06645"/>
      <origin xyz="-1.31E-02 7.00E-06 2.12E-02" rpy="0 ${M_PI/8} 0"/>
      <inertia ixx="1.66E-05" ixy="1.80E-09" ixz="-5.75E-07" iyy="2.36E-05" iyz="-3.23E-08" izz="1.77E-05"/>
    </inertial>
  </link>

  <joint name="${NAME_JOINT_1}" type="revolute">
    <origin xyz="0 0 0.0454" rpy="0 0 0"/>
    <axis xyz="0 0 1"/>
    <limit
      effort="10.0"
      velocity="${joints_vlimit}"
      lower="${joint1_lower_limit}"
      upper="${joint1_upper_limit}"
      />
    <parent link="${NAME_LINK_BASE}"/>
    <child link="${NAME_LINK_1}"/>
    <dynamics damping="1.0e-6" friction="2.0e-1"/>
  </joint>

  </xacro:macro>
</robot>