<?xml version="1.0"?>

<robot xmlns:xacro="http://ros.org/wiki/xacro">
  <material name="black">
    <color rgba="0.2 0.2 0.2 1.0"/>
  </material>
  <material name="grey">
    <color rgba="0.4 0.4 0.4 1.0"/>
  </material>
  <material name="white">
    <color rgba="0.9 0.9 0.9 1.0"/>
  </material>

  <xacro:property name="joint_effort_limit" value="10.0"/>
  <xacro:property name="joint_velocity_limit" value="1.0"/>
  <xacro:property name="TO_RADIAN" value="${pi / 180.0}"/>


  <link name="base_link"/>

  <joint name="base_to_arm_base" type="fixed">
    <origin xyz="0 0 0.065" rpy="0 0 0"/>
    <parent link="base_link"/>
    <child link="arm_base_link"/>
  </joint>

  <joint name="arm_base_to_arm_link1" type="revolute">
    <origin xyz="0 0 0" rpy="0 0 0"/>
    <axis xyz="0 0 1"/>
    <parent link="arm_base_link"/>
    <child link="arm_link1"/>
    <limit effort="${joint_effort_limit}" velocity="${joint_velocity_limit}" lower="${-180*TO_RADIAN}" upper="${180*TO_RADIAN}" />
  </joint>

  <joint name="arm_link1_to_arm_link2" type="revolute">
    <origin xyz="0.015 -0.02 0.0" rpy="${pi/2} 0 0"/>
    <axis xyz="0 0 1"/>
    <parent link="arm_link1"/>
    <child link="arm_link2"/>
    <limit effort="${joint_effort_limit}" velocity="${joint_velocity_limit}" lower="${-10*TO_RADIAN}" upper="${180*TO_RADIAN}" />
  </joint>

  <joint name="arm_link2_to_arm_link3" type="revolute">
    <origin xyz="0.1 0.0 0.0" rpy="0 0 0"/>
    <axis xyz="0 0 1"/>
    <parent link="arm_link2"/>
    <child link="arm_link3"/>
    <limit effort="${joint_effort_limit}" velocity="${joint_velocity_limit}" lower="${-150*TO_RADIAN}" upper="${150*TO_RADIAN}" />
  </joint>

  <joint name="arm_link3_to_arm_link4" type="revolute">
    <origin xyz="0.125 0.0 -0.014" rpy="0 0 ${-pi/2}"/>
    <axis xyz="0 0 1"/>
    <parent link="arm_link3"/>
    <child link="arm_link4"/>
    <limit effort="${joint_effort_limit}" velocity="${joint_velocity_limit}" lower="${-90*TO_RADIAN}" upper="${90*TO_RADIAN}" />
  </joint>

  <joint name="arm_link4_to_shinai_link" type="revolute">
    <origin xyz="0.016 0.075 0.0" rpy="${pi/2} 0 ${pi}"/>
    <axis xyz="0 0 1"/>
    <parent link="arm_link4"/>
    <child link="shinai_link"/>
    <limit effort="${joint_effort_limit}" velocity="${joint_velocity_limit}" lower="${-180*TO_RADIAN}" upper="${180*TO_RADIAN}" />
  </joint>

  <link name="arm_base_link">
    <visual>
      <origin xyz="0 0 -0.065" rpy="0 0 0"/>
      <geometry>
        <mesh filename="package://ken_description/meshes/arm_base.stl" scale="1 1 1"/>
      </geometry>
      <material name="grey"/>
    </visual>
    <collision>
      <origin xyz="0 0 -0.065" rpy="0 0 0"/>
      <geometry>
        <mesh filename="package://ken_description/meshes/arm_base.stl" scale="1 1 1"/>
      </geometry>
    </collision>
    <inertial>
      <mass value="0.3"/>
      <origin xyz="0.0 0.0 0.0" rpy="0 0 0"/>
      <inertia ixx="0.1" ixy="0.1" ixz="0.1" iyy="0.1" iyz="0.1" izz="0.1"/>
    </inertial>
  </link>

  <link name="arm_link1">
    <visual>
      <origin xyz="0 0 -0.023" rpy="0 0 0"/>
      <geometry>
        <mesh filename="package://ken_description/meshes/link1.stl" scale="1 1 1"/>
      </geometry>
      <material name="white"/>
    </visual>
    <collision>
      <origin xyz="0 0 -0.023" rpy="0 0 0"/>
      <geometry>
        <mesh filename="package://ken_description/meshes/link1.stl" scale="1 1 1"/>
      </geometry>
    </collision>
    <inertial>
      <mass value="0.3"/>
      <origin xyz="0.0 0.0 0.0" rpy="0 0 0"/>
      <inertia ixx="0.1" ixy="0.1" ixz="0.1" iyy="0.1" iyz="0.1" izz="0.1"/>
    </inertial>
  </link>

  <link name="arm_link2">
    <visual>
      <origin xyz="0 0 0" rpy="${-pi/2} 0 0"/>
      <geometry>
        <mesh filename="package://ken_description/meshes/link2.stl" scale="1 1 1"/>
      </geometry>
      <material name="grey"/>
    </visual>
    <collision>
      <origin xyz="0 0 0" rpy="${-pi/2} 0 0"/>
      <geometry>
        <mesh filename="package://ken_description/meshes/link2.stl" scale="1 1 1"/>
      </geometry>
    </collision>
    <inertial>
      <mass value="0.3"/>
      <origin xyz="0.0 0.0 0.0" rpy="0 0 0"/>
      <inertia ixx="0.1" ixy="0.1" ixz="0.1" iyy="0.1" iyz="0.1" izz="0.1"/>
    </inertial>
  </link>

  <link name="arm_link3">
    <visual>
      <origin xyz="0 0 0" rpy="${-pi/2} 0 ${pi/2}"/>
      <geometry>
        <mesh filename="package://ken_description/meshes/link3.stl" scale="1 1 1"/>
      </geometry>
      <material name="white"/>
    </visual>
    <collision>
      <origin xyz="0 0 0" rpy="${-pi/2} 0 ${pi/2}"/>
      <geometry>
        <mesh filename="package://ken_description/meshes/link3.stl" scale="1 1 1"/>
      </geometry>
    </collision>
    <inertial>
      <mass value="0.3"/>
      <origin xyz="0.0 0.0 0.0" rpy="0 0 0"/>
      <inertia ixx="0.1" ixy="0.1" ixz="0.1" iyy="0.1" iyz="0.1" izz="0.1"/>
    </inertial>
  </link>

  <link name="arm_link4">
    <visual>
      <origin xyz="0 0 0.014" rpy="${-pi/2} 0 ${pi}"/>
      <geometry>
        <mesh filename="package://ken_description/meshes/link4.stl" scale="1 1 1"/>
      </geometry>
      <material name="grey"/>
    </visual>
    <collision>
      <origin xyz="0 0 0.014" rpy="${-pi/2} 0 ${pi}"/>
      <geometry>
        <mesh filename="package://ken_description/meshes/link4.stl" scale="1 1 1"/>
      </geometry>
    </collision>
    <inertial>
      <mass value="0.3"/>
      <origin xyz="0.0 0.0 0.0" rpy="0 0 0"/>
      <inertia ixx="0.1" ixy="0.1" ixz="0.1" iyy="0.1" iyz="0.1" izz="0.1"/>
    </inertial>
  </link>

  <link name="shinai_link">
    <visual>
      <origin xyz="0 0 0" rpy="${pi/2} 0 ${pi/2}"/>
      <geometry>
        <mesh filename="package://ken_description/meshes/shinai.stl" scale="1 1 1"/>
      </geometry>
      <material name="white"/>
    </visual>
    <collision>
      <origin xyz="0 0 0" rpy="${pi/2} 0 ${pi/2}"/>
      <geometry>
        <mesh filename="package://ken_description/meshes/shinai.stl" scale="1 1 1"/>
      </geometry>
    </collision>
    <inertial>
      <mass value="0.3"/>
      <origin xyz="0.0 0.0 0.0" rpy="0 0 0"/>
      <inertia ixx="0.1" ixy="0.1" ixz="0.1" iyy="0.1" iyz="0.1" izz="0.1"/>
    </inertial>
  </link>

</robot>